<?xml version="1.0" encoding="utf-8"?>
<robot xmlns:xacro="http://www.ros.org/wiki/xacro" name="hand">
  <xacro:macro name="hand" params="connected_to:='' ns:='' rpy:='0 0 0' xyz:='0 0 0' ">
    <xacro:unless value="${connected_to == ''}">
      <joint name="${ns}_hand_joint" type="fixed">
        <parent link="${connected_to}"/>
        <child link="${ns}_hand"/>
        <origin xyz="${xyz}" rpy="${rpy}"/>
      </joint>
    </xacro:unless>
    <link name="${ns}_hand">
      <visual>
        <geometry>
          <mesh filename="package://franka_description/meshes/visual/hand.dae"/>
        </geometry>
      </visual>
      <collision>
        <geometry>
          <mesh filename="package://franka_description/meshes/collision/hand.stl"/>
        </geometry>
      </collision>

      <!-- for simulation -->
      <inertial>
        <origin xyz="0 0 0" rpy="0 0 0" />
        <mass value="0.68" />
        <inertia ixx="0.1" ixy="0.0" ixz="0.0" iyy="0.1" iyz="0.0" izz="0.1" />
      </inertial>
      <!-- end for simulation -->
    </link>
    <link name="${ns}_leftfinger">
      <visual>
        <geometry>
          <mesh filename="package://franka_description/meshes/visual/finger.dae"/>
        </geometry>
      </visual>
      <collision>
        <geometry>
          <mesh filename="package://franka_description/meshes/collision/finger.stl"/>
        </geometry>
      </collision>

      <!-- for simulation -->
      <inertial>
        <origin xyz="0 0 0" rpy="0 0 0" />
        <mass value="0.01" />
        <inertia ixx="0.1" ixy="0.0" ixz="0.0" iyy="0.1" iyz="0.0" izz="0.1" />
      </inertial>
      <!-- end for simulation -->
    </link>
    <link name="${ns}_rightfinger">
      <visual>
        <origin xyz="0 0 0" rpy="0 0 ${pi}"/>
        <geometry>
          <mesh filename="package://franka_description/meshes/visual/finger.dae"/>
        </geometry>
      </visual>
      <collision>
        <origin xyz="0 0 0" rpy="0 0 ${pi}"/>
        <geometry>
          <mesh filename="package://franka_description/meshes/collision/finger.stl"/>
        </geometry>
      </collision>

      <!-- for simulation -->
      <inertial>
        <origin xyz="0 0 0" rpy="0 0 0" />
        <mass value="0.01" />
        <inertia ixx="0.1" ixy="0.0" ixz="0.0" iyy="0.1" iyz="0.0" izz="0.1" />
      </inertial>
      <!-- end for simulation -->
    </link>
    <joint name="${ns}_finger_joint1" type="prismatic">
      <parent link="${ns}_hand"/>
      <child link="${ns}_leftfinger"/>
      <origin xyz="0 0 0.0584" rpy="0 0 0"/>
      <axis xyz="0 1 0"/>
      <limit effort="20" lower="0.0" upper="0.04" velocity="0.2"/>
    </joint>
    <joint name="${ns}_finger_joint2" type="prismatic">
      <parent link="${ns}_hand"/>
      <child link="${ns}_rightfinger"/>
      <origin xyz="0 0 0.0584" rpy="0 0 0"/>
      <axis xyz="0 -1 0"/>
      <limit effort="20" lower="0.0" upper="0.04" velocity="0.2"/>
    </joint>

    <!-- attach a camera frame -->
    <link name="${ns}_camera_link">
      <visual>
        <origin xyz="0 0 0" rpy="0 0 0" />
        <geometry>
          <box size="0.01 0.1 0.03" />
        </geometry>
        <material name="cam_color">
          <color rgba="0. 1. 0. 0.3" />
        </material>
      </visual>
      <inertial>
        <origin xyz="0 0 0" rpy="0 0 0" />
        <mass value="0.01" />
        <inertia ixx="0.1" ixy="0.0" ixz="0.0" iyy="0.1" iyz="0.0" izz="0.1" />
      </inertial>
    </link>

    <joint name="${ns}_camera_joint" type="fixed">
      <parent link="${ns}_hand" />
      <child link="${ns}_camera_link" />
      <origin xyz="0.1 0 0" rpy="0 ${-pi/2} ${pi}" />
    </joint>
    <!--
    <link name="${ns}_camera_optical_frame" />
    <joint name="${ns}_camera_optical_joint" type="fixed">
      <parent link="${ns}_camera_link" />
      <child link="${ns}_camera_optical_frame" />
      <origin xyz="0 0 0" rpy="${-pi/2} 0 ${-pi/2}" />
    </joint>
    -->

    <gazebo reference="${ns}_camera_link">
      <sensor type="camera" name="${ns}_camera">
        <update_rate>10.0</update_rate>
        <camera name="camera">
          <horizontal_fov>1.396</horizontal_fov>
          <image>
            <width>640</width>
            <height>480</height>
            <format>R8G8B8</format>
          </image>
          <clip>
            <near>0.02</near>
            <far>30</far>
          </clip>
          <noise>
            <type>gaussian</type>
            <mean>0.0</mean>
            <stddev>0.007</stddev>
          </noise>
        </camera>
        <plugin name="camera_controller" filename="libgazebo_ros_camera.so">
          <alwaysOn>true</alwaysOn>
          <updateRate>0.0</updateRate>
          <cameraName>${ns}/camera</cameraName>
          <imageTopicName>image_raw</imageTopicName>
          <cameraInfoTopicName>camera_info</cameraInfoTopicName>
          <frameName>${ns}_camera_optical_frame</frameName>
          <hackBaseline>0.07</hackBaseline>
          <distortionK1>0.0</distortionK1>
          <distortionK2>0.0</distortionK2>
          <distortionK3>0.0</distortionK3>
          <distortionT1>0.0</distortionT1>
          <distortionT2>0.0</distortionT2>
        </plugin>
      </sensor>
    </gazebo>

  </xacro:macro>
</robot>
